Workbook

Sheet Agentic
A1: AITBM — Quick AI Risk Self-Assessment — Agentic / MCP
A2: Scenario: Agentic / MCP. Answer Yes or No in column C; the Effective Risk Score (ERS) updates automatically. The Agentic / RAG / Standalone tabs each carry questions tailored to that architecture. Educational estimate; see the AITBM Framework Specification for assessments of record.
A4: A | B4: About your system — A few questions about what your AI agent does and where it runs.
B5: Can the agent take actions or make decisions on its own, without a person approving each step? | C5: No
B6: Can it reach untrusted input — the public internet, external tools/APIs, or third-party content? | C6: No
B7: Could a wrong action cause serious harm — money moved, data changed, safety, or many systems affected? | C7: No
B8: Would a bad action be slow or hard to undo (no kill-switch, no quick rollback, vendor lock-in)? | C8: No
A10: B | B10: Safeguards in place — Answer Yes only for protections you have actually implemented. | D10: Points you could save
B11: Is the agent restricted to least-privilege — limited actions, tools, and systems it can reach? | C11: No | D11: =IF('Agentic'!$C$11="Yes","",ROUND('Agentic Engine'!B49,1))
B12: Does a human review or approve the agent's high-impact actions before they take effect? | C12: No | D12: =IF('Agentic'!$C$12="Yes","",ROUND('Agentic Engine'!B50,1))
B13: Do you verify each agent's identity and monitor agent behavior for anomalies? | C13: No | D13: =IF('Agentic'!$C$13="Yes","",ROUND('Agentic Engine'!B51,1))
B14: Do you control which tools/skills the agent may use, and route its calls through a vetted gateway? | C14: No | D14: =IF('Agentic'!$C$14="Yes","",ROUND('Agentic Engine'!B52,1))
B15: Is the agent sandboxed and network-segmented away from sensitive systems? | C15: No | D15: =IF('Agentic'!$C$15="Yes","",ROUND('Agentic Engine'!B53,1))
B16: Do you filter and validate both the inputs the agent receives and the outputs/actions it produces? | C16: No | D16: =IF('Agentic'!$C$16="Yes","",ROUND('Agentic Engine'!B54,1))
B17: Do you have real-time detection for prompt injection, tool abuse, or abnormal agent behavior? | C17: No | D17: =IF('Agentic'!$C$17="Yes","",ROUND('Agentic Engine'!B55,1))
B18: Do you track the agent's tools/model/data provenance (inventory, lineage) and document expected behavior? | C18: No | D18: =IF('Agentic'!$C$18="Yes","",ROUND('Agentic Engine'!B56,1))
A20: C | B20: Evidence & assurance — How well the system's security is documented and tested.
B21: Do you have an AIBOM / model card AND an inventory of the agent's tools and their sources? | C21: No
B22: Have you red-teamed the agent (tool abuse, prompt injection, privilege escalation)? | C22: No
B23: Was that testing recent (within ~12 months) and repeated after changes to tools or prompts? | C23: No
A26: RESULT
B27: Effective Risk Score (ERS) | C27: =ROUND('Agentic Engine'!B46,1)
B28: Severity | C28: =IF('Agentic Engine'!B46>=9,"Critical",IF('Agentic Engine'!B46>=7,"High",IF('Agentic Engine'!B46>=5,"Moderate",IF('Agentic Engine'!B46>=3,"Low-Moderate","Low"))))
B29: Scenario | C29: Agentic / MCP

Sheet Agentic Engine
A1: metric | B1: axis | C1: base | D1: value
A2: Ro-1 | B2: Ro | C2: 0.2 | D2: =MAX(C2,IF('Agentic'!$C$16="Yes",0.65,0),IF('Agentic'!$C$17="Yes",0.75,0))
A3: Ro-2 | B3: Ro | C3: 0.5 | D3: =MAX(C3)
A4: Ro-3 | B4: Ro | C4: 0.25 | D4: =MAX(C4,IF('Agentic'!$C$17="Yes",0.65,0),IF('Agentic'!$C$18="Yes",0.7,0))
A5: Ro-4 | B5: Ro | C5: 0.15 | D5: =MAX(C5,IF('Agentic'!$C$14="Yes",0.55,0),IF('Agentic'!$C$17="Yes",0.55,0),IF('Agentic'!$C$18="Yes",0.7,0))
A6: Fa-1 | B6: Fa | C6: 0.5 | D6: =MAX(C6)
A7: Fa-2 | B7: Fa | C7: 0.5 | D7: =MAX(C7)
A8: Fa-3 | B8: Fa | C8: 0.5 | D8: =MAX(C8)
A9: Fa-4 | B9: Fa | C9: 0.5 | D9: =MAX(C9)
A10: Tr-1 | B10: Tr | C10: 0.5 | D10: =MAX(C10,IF('Agentic'!$C$18="Yes",0.6,0))
A11: Tr-2 | B11: Tr | C11: 0.3 | D11: =MAX(C11,IF('Agentic'!$C$16="Yes",0.7,0),IF('Agentic'!$C$17="Yes",0.6,0),IF('Agentic'!$C$18="Yes",0.75,0))
A12: Tr-3 | B12: Tr | C12: 0.4 | D12: =MAX(C12,IF('Agentic'!$C$17="Yes",0.65,0))
A13: Tr-4 | B13: Tr | C13: 0 | D13: =MAX(C13,IF('Agentic'!$C$18="Yes",0.8,0))
A14: Pr-1 | B14: Pr | C14: 0.25 | D14: =MAX(C14,IF('Agentic'!$C$16="Yes",0.6,0))
A15: Pr-2 | B15: Pr | C15: 0.3 | D15: =MAX(C15)
A16: Pr-3 | B16: Pr | C16: 0.3 | D16: =MAX(C16,IF('Agentic'!$C$18="Yes",0.7,0))
A17: Pr-4 | B17: Pr | C17: 0.5 | D17: =MAX(C17)
A18: Cn-1 | B18: Cn | C18: 0.1 | D18: =MAX(C18,IF('Agentic'!$C$11="Yes",0.8,0),IF('Agentic'!$C$12="Yes",0.75,0),IF('Agentic'!$C$13="Yes",0.75,0),IF('Agentic'!$C$14="Yes",0.65,0),IF('Agentic'!$C$15="Yes",0.7,0),IF('Agentic'!$C$18="Yes",0.6,0))
A19: Cn-2 | B19: Cn | C19: 0.15 | D19: =MAX(C19,IF('Agentic'!$C$11="Yes",0.75,0),IF('Agentic'!$C$12="Yes",0.7,0),IF('Agentic'!$C$13="Yes",0.7,0))
A20: Cn-3 | B20: Cn | C20: 0.1 | D20: =MAX(C20,IF('Agentic'!$C$15="Yes",0.65,0),IF('Agentic'!$C$16="Yes",0.75,0))
A21: Cn-4 | B21: Cn | C21: 0.2 | D21: =MAX(C21,IF('Agentic'!$C$14="Yes",0.55,0),IF('Agentic'!$C$15="Yes",0.6,0))
A22: Cn-5 | B22: Cn | C22: 0.2 | D22: =MAX(C22,IF('Agentic'!$C$11="Yes",0.7,0),IF('Agentic'!$C$13="Yes",0.8,0))
A23: axis averages
A24: Ro | B24: =AVERAGE(D2:D5)
A25: Fa | B25: =AVERAGE(D6:D9)
A26: Tr | B26: =AVERAGE(D10:D13)
A27: Pr | B27: =AVERAGE(D14:D17)
A28: Cn | B28: =AVERAGE(D18:D22)
A30: IVP | B30: =0.15*B24+0.1*B25+0.15*B26+0.15*B27+0.45*B28
A32: aa | B32: =IF('Agentic'!$C$5="Yes",0.85,0.3)
A33: as | B33: =IF('Agentic'!$C$6="Yes",0.85,0.3)
A34: cp | B34: =IF('Agentic'!$C$7="Yes",0.85,0.3)
A35: rf | B35: =IF('Agentic'!$C$8="Yes",0.85,0.3)
A36: orp_avg | B36: =AVERAGE(B32:B35)
A37: n_elev | B37: =(IF(B32>0.75,1,0)+IF(B33>0.75,1,0)+IF(B34>0.75,1,0)+IF(B35>0.75,1,0))
A38: CRM | B38: =MIN(1.75,MAX(0.75,-0.129+1.882*B36+0.05*B37))
A40: pc | B40: =IF('Agentic'!$C$21="Yes",0.8,0.2)
A41: ec | B41: =IF('Agentic'!$C$22="Yes",0.8,0.2)
A42: tf | B42: =IF('Agentic'!$C$22="Yes",IF('Agentic'!$C$23="Yes",0.8,0.25),0.2)
A43: ACI | B43: =(MAX(B40,0.01)*MAX(B41,0.01)*MAX(B42,0.01))^(1/3)
...

Sheet RAG
A1: AITBM — Quick AI Risk Self-Assessment — RAG
A2: Scenario: RAG. Answer Yes or No in column C; the Effective Risk Score (ERS) updates automatically. The Agentic / RAG / Standalone tabs each carry questions tailored to that architecture. Educational estimate; see the AITBM Framework Specification for assessments of record.
A4: A | B4: About your system — A few questions about your retrieval-augmented (RAG) system and its data.
B5: Does the system act on retrieved content automatically (e.g., trigger actions), rather than only answering? | C5: No
B6: Can untrusted or externally-sourced documents enter the knowledge base, or be retrieved at query time? | C6: No
B7: Could a wrong or poisoned answer cause serious harm (financial, legal, safety, or a wide audience)? | C7: No
B8: Would correcting a bad answer be slow (re-indexing, re-embedding, vendor dependency, no quick fix)? | C8: No
A10: B | B10: Safeguards in place — Answer Yes only for protections you have actually implemented. | D10: Points you could save
B11: Is your RAG pipeline secured — retrieved content validated and access-controlled before use? | C11: No | D11: =IF('RAG'!$C$11="Yes","",ROUND('RAG Engine'!B49,1))
B12: Do you detect and block leakage of sensitive or personal data in answers? | C12: No | D12: =IF('RAG'!$C$12="Yes","",ROUND('RAG Engine'!B50,1))
B13: Do you filter and validate both the user query and the generated answer? | C13: No | D13: =IF('RAG'!$C$13="Yes","",ROUND('RAG Engine'!B51,1))
B14: Do you detect indirect prompt injection carried inside retrieved documents? | C14: No | D14: =IF('RAG'!$C$14="Yes","",ROUND('RAG Engine'!B52,1))
B15: Do you resist data poisoning of the corpus or training data (vetting, adversarial hardening)? | C15: No | D15: =IF('RAG'!$C$15="Yes","",ROUND('RAG Engine'!B53,1))
B16: Do you track provenance/lineage of the model AND the knowledge-base sources? | C16: No | D16: =IF('RAG'!$C$16="Yes","",ROUND('RAG Engine'!B54,1))
B17: Are the vector store, secrets, and backend isolated and network-segmented? | C17: No | D17: =IF('RAG'!$C$17="Yes","",ROUND('RAG Engine'!B55,1))
B18: Do you monitor for retrieval drift/anomalies and document the system's expected behavior? | C18: No | D18: =IF('RAG'!$C$18="Yes","",ROUND('RAG Engine'!B56,1))
A20: C | B20: Evidence & assurance — How well the system's security is documented and tested.
B21: Do you document provenance for the model AND the knowledge-base sources (AIBOM / data lineage)? | C21: No
B22: Have you security-tested the RAG pipeline (data poisoning, indirect injection, data leakage)? | C22: No
B23: Was that testing recent (within ~12 months) and re-run when the corpus changed? | C23: No
A26: RESULT
B27: Effective Risk Score (ERS) | C27: =ROUND('RAG Engine'!B46,1)
B28: Severity | C28: =IF('RAG Engine'!B46>=9,"Critical",IF('RAG Engine'!B46>=7,"High",IF('RAG Engine'!B46>=5,"Moderate",IF('RAG Engine'!B46>=3,"Low-Moderate","Low"))))
B29: Scenario | C29: RAG

Sheet RAG Engine
A1: metric | B1: axis | C1: base | D1: value
A2: Ro-1 | B2: Ro | C2: 0.2 | D2: =MAX(C2,IF('RAG'!$C$13="Yes",0.65,0),IF('RAG'!$C$14="Yes",0.75,0),IF('RAG'!$C$15="Yes",0.7,0))
A3: Ro-2 | B3: Ro | C3: 0.5 | D3: =MAX(C3)
A4: Ro-3 | B4: Ro | C4: 0.25 | D4: =MAX(C4,IF('RAG'!$C$18="Yes",0.7,0))
A5: Ro-4 | B5: Ro | C5: 0.15 | D5: =MAX(C5,IF('RAG'!$C$11="Yes",0.7,0),IF('RAG'!$C$15="Yes",0.65,0),IF('RAG'!$C$16="Yes",0.7,0),IF('RAG'!$C$18="Yes",0.55,0))
A6: Fa-1 | B6: Fa | C6: 0.5 | D6: =MAX(C6)
A7: Fa-2 | B7: Fa | C7: 0.5 | D7: =MAX(C7)
A8: Fa-3 | B8: Fa | C8: 0.5 | D8: =MAX(C8)
A9: Fa-4 | B9: Fa | C9: 0.5 | D9: =MAX(C9)
A10: Tr-1 | B10: Tr | C10: 0.5 | D10: =MAX(C10,IF('RAG'!$C$18="Yes",0.6,0))
A11: Tr-2 | B11: Tr | C11: 0.3 | D11: =MAX(C11,IF('RAG'!$C$13="Yes",0.7,0),IF('RAG'!$C$18="Yes",0.75,0))
A12: Tr-3 | B12: Tr | C12: 0.4 | D12: =MAX(C12,IF('RAG'!$C$14="Yes",0.65,0))
A13: Tr-4 | B13: Tr | C13: 0 | D13: =MAX(C13,IF('RAG'!$C$16="Yes",0.8,0))
A14: Pr-1 | B14: Pr | C14: 0.25 | D14: =MAX(C14,IF('RAG'!$C$12="Yes",0.7,0),IF('RAG'!$C$13="Yes",0.6,0))
A15: Pr-2 | B15: Pr | C15: 0.3 | D15: =MAX(C15,IF('RAG'!$C$11="Yes",0.65,0))
A16: Pr-3 | B16: Pr | C16: 0.3 | D16: =MAX(C16,IF('RAG'!$C$12="Yes",0.65,0),IF('RAG'!$C$16="Yes",0.7,0))
A17: Pr-4 | B17: Pr | C17: 0.5 | D17: =MAX(C17)
A18: Cn-1 | B18: Cn | C18: 0.1 | D18: =MAX(C18,IF('RAG'!$C$16="Yes",0.6,0),IF('RAG'!$C$17="Yes",0.7,0))
A19: Cn-2 | B19: Cn | C19: 0.15 | D19: =MAX(C19)
A20: Cn-3 | B20: Cn | C20: 0.1 | D20: =MAX(C20,IF('RAG'!$C$11="Yes",0.7,0),IF('RAG'!$C$12="Yes",0.7,0),IF('RAG'!$C$13="Yes",0.75,0),IF('RAG'!$C$17="Yes",0.65,0))
A21: Cn-4 | B21: Cn | C21: 0.2 | D21: =MAX(C21,IF('RAG'!$C$17="Yes",0.6,0))
A22: Cn-5 | B22: Cn | C22: 0.2 | D22: =MAX(C22)
A23: axis averages
A24: Ro | B24: =AVERAGE(D2:D5)
A25: Fa | B25: =AVERAGE(D6:D9)
A26: Tr | B26: =AVERAGE(D10:D13)
A27: Pr | B27: =AVERAGE(D14:D17)
A28: Cn | B28: =AVERAGE(D18:D22)
A30: IVP | B30: =0.25*B24+0.1*B25+0.15*B26+0.3*B27+0.2*B28
A32: aa | B32: =IF('RAG'!$C$5="Yes",0.85,0.3)
A33: as | B33: =IF('RAG'!$C$6="Yes",0.85,0.3)
A34: cp | B34: =IF('RAG'!$C$7="Yes",0.85,0.3)
A35: rf | B35: =IF('RAG'!$C$8="Yes",0.85,0.3)
A36: orp_avg | B36: =AVERAGE(B32:B35)
A37: n_elev | B37: =(IF(B32>0.75,1,0)+IF(B33>0.75,1,0)+IF(B34>0.75,1,0)+IF(B35>0.75,1,0))
A38: CRM | B38: =MIN(1.75,MAX(0.75,-0.129+1.882*B36+0.05*B37))
A40: pc | B40: =IF('RAG'!$C$21="Yes",0.8,0.2)
A41: ec | B41: =IF('RAG'!$C$22="Yes",0.8,0.2)
A42: tf | B42: =IF('RAG'!$C$22="Yes",IF('RAG'!$C$23="Yes",0.8,0.25),0.2)
A43: ACI | B43: =(MAX(B40,0.01)*MAX(B41,0.01)*MAX(B42,0.01))^(1/3)
...

Sheet Standalone
A1: AITBM — Quick AI Risk Self-Assessment — Standalone LLM
A2: Scenario: Standalone LLM. Answer Yes or No in column C; the Effective Risk Score (ERS) updates automatically. The Agentic / RAG / Standalone tabs each carry questions tailored to that architecture. Educational estimate; see the AITBM Framework Specification for assessments of record.
A4: A | B4: About your system — A few questions about your standalone model or chatbot and how it is used.
B5: Are the model's outputs used to drive decisions or actions automatically, without human review? | C5: No
B6: Can the public or untrusted users send prompts or inputs to the model? | C6: No
B7: Could a wrong output cause serious harm (financial, legal, safety, or many users)? | C7: No
B8: Would fixing a discovered flaw be slow (retraining, fine-tuning, vendor dependency)? | C8: No
A10: B | B10: Safeguards in place — Answer Yes only for protections you have actually implemented. | D10: Points you could save
B11: Have you adversarially trained and tested the model against manipulated inputs? | C11: No | D11: =IF('Standalone'!$C$11="Yes","",ROUND('Standalone Engine'!B49,1))
B12: Do you filter and validate both the inputs users send and the outputs the model returns? | C12: No | D12: =IF('Standalone'!$C$12="Yes","",ROUND('Standalone Engine'!B50,1))
B13: Do you have real-time detection for prompt injection and jailbreak attempts? | C13: No | D13: =IF('Standalone'!$C$13="Yes","",ROUND('Standalone Engine'!B51,1))
B14: Have you baselined the model's expected behavior/output consistency and documented it? | C14: No | D14: =IF('Standalone'!$C$14="Yes","",ROUND('Standalone Engine'!B52,1))
B15: Do you detect and block leakage of sensitive or personal data in outputs? | C15: No | D15: =IF('Standalone'!$C$15="Yes","",ROUND('Standalone Engine'!B53,1))
B16: Do you track where the model and its training data came from (lineage / AIBOM)? | C16: No | D16: =IF('Standalone'!$C$16="Yes","",ROUND('Standalone Engine'!B54,1))
B17: Do you monitor for model drift and anomalies in production? | C17: No | D17: =IF('Standalone'!$C$17="Yes","",ROUND('Standalone Engine'!B55,1))
B18: Is the model's runtime isolated and granted only least-access to surrounding systems? | C18: No | D18: =IF('Standalone'!$C$18="Yes","",ROUND('Standalone Engine'!B56,1))
A20: C | B20: Evidence & assurance — How well the system's security is documented and tested.
B21: Do you have a model card / AIBOM documenting the model and its training-data provenance? | C21: No
B22: Have you security-tested the model (adversarial inputs, jailbreaks, data extraction)? | C22: No
B23: Was that testing recent (within ~12 months) and kept current with model updates? | C23: No
A26: RESULT
B27: Effective Risk Score (ERS) | C27: =ROUND('Standalone Engine'!B46,1)
B28: Severity | C28: =IF('Standalone Engine'!B46>=9,"Critical",IF('Standalone Engine'!B46>=7,"High",IF('Standalone Engine'!B46>=5,"Moderate",IF('Standalone Engine'!B46>=3,"Low-Moderate","Low"))))
B29: Scenario | C29: Standalone LLM

Sheet Standalone Engine
A1: metric | B1: axis | C1: base | D1: value
A2: Ro-1 | B2: Ro | C2: 0.2 | D2: =MAX(C2,IF('Standalone'!$C$11="Yes",0.7,0),IF('Standalone'!$C$12="Yes",0.65,0),IF('Standalone'!$C$13="Yes",0.75,0))
A3: Ro-2 | B3: Ro | C3: 0.5 | D3: =MAX(C3)
A4: Ro-3 | B4: Ro | C4: 0.25 | D4: =MAX(C4,IF('Standalone'!$C$14="Yes",0.7,0),IF('Standalone'!$C$17="Yes",0.65,0))
A5: Ro-4 | B5: Ro | C5: 0.15 | D5: =MAX(C5,IF('Standalone'!$C$11="Yes",0.65,0),IF('Standalone'!$C$16="Yes",0.7,0),IF('Standalone'!$C$17="Yes",0.55,0))
A6: Fa-1 | B6: Fa | C6: 0.5 | D6: =MAX(C6)
A7: Fa-2 | B7: Fa | C7: 0.5 | D7: =MAX(C7)
A8: Fa-3 | B8: Fa | C8: 0.5 | D8: =MAX(C8)
A9: Fa-4 | B9: Fa | C9: 0.5 | D9: =MAX(C9)
A10: Tr-1 | B10: Tr | C10: 0.5 | D10: =MAX(C10,IF('Standalone'!$C$14="Yes",0.6,0))
A11: Tr-2 | B11: Tr | C11: 0.3 | D11: =MAX(C11,IF('Standalone'!$C$12="Yes",0.7,0),IF('Standalone'!$C$14="Yes",0.75,0),IF('Standalone'!$C$17="Yes",0.6,0))
A12: Tr-3 | B12: Tr | C12: 0.4 | D12: =MAX(C12,IF('Standalone'!$C$13="Yes",0.65,0))
A13: Tr-4 | B13: Tr | C13: 0 | D13: =MAX(C13,IF('Standalone'!$C$16="Yes",0.8,0))
A14: Pr-1 | B14: Pr | C14: 0.25 | D14: =MAX(C14,IF('Standalone'!$C$12="Yes",0.6,0),IF('Standalone'!$C$15="Yes",0.7,0))
A15: Pr-2 | B15: Pr | C15: 0.3 | D15: =MAX(C15)
A16: Pr-3 | B16: Pr | C16: 0.3 | D16: =MAX(C16,IF('Standalone'!$C$15="Yes",0.65,0),IF('Standalone'!$C$16="Yes",0.7,0))
A17: Pr-4 | B17: Pr | C17: 0.5 | D17: =MAX(C17)
A18: Cn-1 | B18: Cn | C18: 0.1 | D18: =MAX(C18,IF('Standalone'!$C$16="Yes",0.6,0),IF('Standalone'!$C$18="Yes",0.7,0))
A19: Cn-2 | B19: Cn | C19: 0.15 | D19: =MAX(C19)
A20: Cn-3 | B20: Cn | C20: 0.1 | D20: =MAX(C20,IF('Standalone'!$C$12="Yes",0.75,0),IF('Standalone'!$C$15="Yes",0.7,0),IF('Standalone'!$C$18="Yes",0.65,0))
A21: Cn-4 | B21: Cn | C21: 0.2 | D21: =MAX(C21,IF('Standalone'!$C$18="Yes",0.6,0))
A22: Cn-5 | B22: Cn | C22: 0.2 | D22: =MAX(C22)
A23: axis averages
A24: Ro | B24: =AVERAGE(D2:D5)
A25: Fa | B25: =AVERAGE(D6:D9)
A26: Tr | B26: =AVERAGE(D10:D13)
A27: Pr | B27: =AVERAGE(D14:D17)
A28: Cn | B28: =AVERAGE(D18:D22)
A30: IVP | B30: =0.25*B24+0.2*B25+0.2*B26+0.2*B27+0.15*B28
A32: aa | B32: =IF('Standalone'!$C$5="Yes",0.85,0.3)
A33: as | B33: =IF('Standalone'!$C$6="Yes",0.85,0.3)
A34: cp | B34: =IF('Standalone'!$C$7="Yes",0.85,0.3)
A35: rf | B35: =IF('Standalone'!$C$8="Yes",0.85,0.3)
A36: orp_avg | B36: =AVERAGE(B32:B35)
A37: n_elev | B37: =(IF(B32>0.75,1,0)+IF(B33>0.75,1,0)+IF(B34>0.75,1,0)+IF(B35>0.75,1,0))
A38: CRM | B38: =MIN(1.75,MAX(0.75,-0.129+1.882*B36+0.05*B37))
A40: pc | B40: =IF('Standalone'!$C$21="Yes",0.8,0.2)
A41: ec | B41: =IF('Standalone'!$C$22="Yes",0.8,0.2)
A42: tf | B42: =IF('Standalone'!$C$22="Yes",IF('Standalone'!$C$23="Yes",0.8,0.25),0.2)
A43: ACI | B43: =(MAX(B40,0.01)*MAX(B41,0.01)*MAX(B42,0.01))^(1/3)
...
